INFO:uvicorn.error:Started server process [3552]
INFO:uvicorn.error:Waiting for application startup.
INFO:uvicorn.error:Application startup complete.
ERROR:uvicorn.error:Exception in ASGI application
Traceback (most recent call last):
  File "C:\Git_Proj\Order-Management-System\.venv\Lib\site-packages\uvicorn\protocols\http\httptools_impl.py", line 409, in run_asgi
    result = await app(  # type: ignore[func-returns-value]
             ^^^^^^^^^^^^^^^^^^^^^^^^^^^^^^^^^^^^^^^^^^^^^^
  File "C:\Git_Proj\Order-Management-System\.venv\Lib\site-packages\uvicorn\middleware\proxy_headers.py", line 60, in __call__
    return await self.app(scope, receive, send)
           ^^^^^^^^^^^^^^^^^^^^^^^^^^^^^^^^^^^^
  File "C:\Git_Proj\Order-Management-System\.venv\Lib\site-packages\fastapi\applications.py", line 1054, in __call__
    await super().__call__(scope, receive, send)
  File "C:\Git_Proj\Order-Management-System\.venv\Lib\site-packages\starlette\applications.py", line 112, in __call__
    await self.middleware_stack(scope, receive, send)
  File "C:\Git_Proj\Order-Management-System\.venv\Lib\site-packages\starlette\middleware\errors.py", line 187, in __call__
    raise exc
  File "C:\Git_Proj\Order-Management-System\.venv\Lib\site-packages\starlette\middleware\errors.py", line 165, in __call__
    await self.app(scope, receive, _send)
  File "C:\Git_Proj\Order-Management-System\.venv\Lib\site-packages\starlette\middleware\exceptions.py", line 62, in __call__
    await wrap_app_handling_exceptions(self.app, conn)(scope, receive, send)
  File "C:\Git_Proj\Order-Management-System\.venv\Lib\site-packages\starlette\_exception_handler.py", line 53, in wrapped_app
    raise exc
  File "C:\Git_Proj\Order-Management-System\.venv\Lib\site-packages\starlette\_exception_handler.py", line 42, in wrapped_app
    await app(scope, receive, sender)
  File "C:\Git_Proj\Order-Management-System\.venv\Lib\site-packages\starlette\routing.py", line 714, in __call__
    await self.middleware_stack(scope, receive, send)
  File "C:\Git_Proj\Order-Management-System\.venv\Lib\site-packages\starlette\routing.py", line 734, in app
    await route.handle(scope, receive, send)
  File "C:\Git_Proj\Order-Management-System\.venv\Lib\site-packages\starlette\routing.py", line 288, in handle
    await self.app(scope, receive, send)
  File "C:\Git_Proj\Order-Management-System\.venv\Lib\site-packages\starlette\routing.py", line 76, in app
    await wrap_app_handling_exceptions(app, request)(scope, receive, send)
  File "C:\Git_Proj\Order-Management-System\.venv\Lib\site-packages\starlette\_exception_handler.py", line 53, in wrapped_app
    raise exc
  File "C:\Git_Proj\Order-Management-System\.venv\Lib\site-packages\starlette\_exception_handler.py", line 42, in wrapped_app
    await app(scope, receive, sender)
  File "C:\Git_Proj\Order-Management-System\.venv\Lib\site-packages\starlette\routing.py", line 73, in app
    response = await f(request)
               ^^^^^^^^^^^^^^^^
  File "C:\Git_Proj\Order-Management-System\.venv\Lib\site-packages\fastapi\routing.py", line 301, in app
    raw_response = await run_endpoint_function(
                   ^^^^^^^^^^^^^^^^^^^^^^^^^^^^
  File "C:\Git_Proj\Order-Management-System\.venv\Lib\site-packages\fastapi\routing.py", line 212, in run_endpoint_function
    return await dependant.call(**values)
           ^^^^^^^^^^^^^^^^^^^^^^^^^^^^^^
  File "C:\Git_Proj\Order-Management-System\app\main.py", line 39, in place_order
    form_data = await request.form()
                ^^^^^^^^^^^^^^^^^^^^
  File "C:\Git_Proj\Order-Management-System\.venv\Lib\site-packages\starlette\requests.py", line 282, in _get_form
    self._form = await form_parser.parse()
                 ^^^^^^^^^^^^^^^^^^^^^^^^^
  File "C:\Git_Proj\Order-Management-System\.venv\Lib\site-packages\starlette\formparsers.py", line 101, in parse
    async for chunk in self.stream:
  File "C:\Git_Proj\Order-Management-System\.venv\Lib\site-packages\starlette\requests.py", line 235, in stream
    raise ClientDisconnect()
starlette.requests.ClientDisconnect
ERROR:uvicorn.error:Exception in ASGI application
Traceback (most recent call last):
  File "C:\Git_Proj\Order-Management-System\.venv\Lib\site-packages\uvicorn\protocols\http\httptools_impl.py", line 409, in run_asgi
    result = await app(  # type: ignore[func-returns-value]
             ^^^^^^^^^^^^^^^^^^^^^^^^^^^^^^^^^^^^^^^^^^^^^^
  File "C:\Git_Proj\Order-Management-System\.venv\Lib\site-packages\uvicorn\middleware\proxy_headers.py", line 60, in __call__
    return await self.app(scope, receive, send)
           ^^^^^^^^^^^^^^^^^^^^^^^^^^^^^^^^^^^^
  File "C:\Git_Proj\Order-Management-System\.venv\Lib\site-packages\fastapi\applications.py", line 1054, in __call__
    await super().__call__(scope, receive, send)
  File "C:\Git_Proj\Order-Management-System\.venv\Lib\site-packages\starlette\applications.py", line 112, in __call__
    await self.middleware_stack(scope, receive, send)
  File "C:\Git_Proj\Order-Management-System\.venv\Lib\site-packages\starlette\middleware\errors.py", line 187, in __call__
    raise exc
  File "C:\Git_Proj\Order-Management-System\.venv\Lib\site-packages\starlette\middleware\errors.py", line 165, in __call__
    await self.app(scope, receive, _send)
  File "C:\Git_Proj\Order-Management-System\.venv\Lib\site-packages\starlette\middleware\exceptions.py", line 62, in __call__
    await wrap_app_handling_exceptions(self.app, conn)(scope, receive, send)
  File "C:\Git_Proj\Order-Management-System\.venv\Lib\site-packages\starlette\_exception_handler.py", line 53, in wrapped_app
    raise exc
  File "C:\Git_Proj\Order-Management-System\.venv\Lib\site-packages\starlette\_exception_handler.py", line 42, in wrapped_app
    await app(scope, receive, sender)
  File "C:\Git_Proj\Order-Management-System\.venv\Lib\site-packages\starlette\routing.py", line 714, in __call__
    await self.middleware_stack(scope, receive, send)
  File "C:\Git_Proj\Order-Management-System\.venv\Lib\site-packages\starlette\routing.py", line 734, in app
    await route.handle(scope, receive, send)
  File "C:\Git_Proj\Order-Management-System\.venv\Lib\site-packages\starlette\routing.py", line 288, in handle
    await self.app(scope, receive, send)
  File "C:\Git_Proj\Order-Management-System\.venv\Lib\site-packages\starlette\routing.py", line 76, in app
    await wrap_app_handling_exceptions(app, request)(scope, receive, send)
  File "C:\Git_Proj\Order-Management-System\.venv\Lib\site-packages\starlette\_exception_handler.py", line 53, in wrapped_app
    raise exc
  File "C:\Git_Proj\Order-Management-System\.venv\Lib\site-packages\starlette\_exception_handler.py", line 42, in wrapped_app
    await app(scope, receive, sender)
  File "C:\Git_Proj\Order-Management-System\.venv\Lib\site-packages\starlette\routing.py", line 73, in app
    response = await f(request)
               ^^^^^^^^^^^^^^^^
  File "C:\Git_Proj\Order-Management-System\.venv\Lib\site-packages\fastapi\routing.py", line 301, in app
    raw_response = await run_endpoint_function(
                   ^^^^^^^^^^^^^^^^^^^^^^^^^^^^
  File "C:\Git_Proj\Order-Management-System\.venv\Lib\site-packages\fastapi\routing.py", line 212, in run_endpoint_function
    return await dependant.call(**values)
           ^^^^^^^^^^^^^^^^^^^^^^^^^^^^^^
  File "C:\Git_Proj\Order-Management-System\app\main.py", line 39, in place_order
    form_data = await request.form()
                ^^^^^^^^^^^^^^^^^^^^
  File "C:\Git_Proj\Order-Management-System\.venv\Lib\site-packages\starlette\requests.py", line 282, in _get_form
    self._form = await form_parser.parse()
                 ^^^^^^^^^^^^^^^^^^^^^^^^^
  File "C:\Git_Proj\Order-Management-System\.venv\Lib\site-packages\starlette\formparsers.py", line 101, in parse
    async for chunk in self.stream:
  File "C:\Git_Proj\Order-Management-System\.venv\Lib\site-packages\starlette\requests.py", line 235, in stream
    raise ClientDisconnect()
starlette.requests.ClientDisconnect
ERROR:uvicorn.error:Exception in ASGI application
Traceback (most recent call last):
  File "C:\Git_Proj\Order-Management-System\.venv\Lib\site-packages\uvicorn\protocols\http\httptools_impl.py", line 409, in run_asgi
    result = await app(  # type: ignore[func-returns-value]
             ^^^^^^^^^^^^^^^^^^^^^^^^^^^^^^^^^^^^^^^^^^^^^^
  File "C:\Git_Proj\Order-Management-System\.venv\Lib\site-packages\uvicorn\middleware\proxy_headers.py", line 60, in __call__
    return await self.app(scope, receive, send)
           ^^^^^^^^^^^^^^^^^^^^^^^^^^^^^^^^^^^^
  File "C:\Git_Proj\Order-Management-System\.venv\Lib\site-packages\fastapi\applications.py", line 1054, in __call__
    await super().__call__(scope, receive, send)
  File "C:\Git_Proj\Order-Management-System\.venv\Lib\site-packages\starlette\applications.py", line 112, in __call__
    await self.middleware_stack(scope, receive, send)
  File "C:\Git_Proj\Order-Management-System\.venv\Lib\site-packages\starlette\middleware\errors.py", line 187, in __call__
    raise exc
  File "C:\Git_Proj\Order-Management-System\.venv\Lib\site-packages\starlette\middleware\errors.py", line 165, in __call__
    await self.app(scope, receive, _send)
  File "C:\Git_Proj\Order-Management-System\.venv\Lib\site-packages\starlette\middleware\exceptions.py", line 62, in __call__
    await wrap_app_handling_exceptions(self.app, conn)(scope, receive, send)
  File "C:\Git_Proj\Order-Management-System\.venv\Lib\site-packages\starlette\_exception_handler.py", line 53, in wrapped_app
    raise exc
  File "C:\Git_Proj\Order-Management-System\.venv\Lib\site-packages\starlette\_exception_handler.py", line 42, in wrapped_app
    await app(scope, receive, sender)
  File "C:\Git_Proj\Order-Management-System\.venv\Lib\site-packages\starlette\routing.py", line 714, in __call__
    await self.middleware_stack(scope, receive, send)
  File "C:\Git_Proj\Order-Management-System\.venv\Lib\site-packages\starlette\routing.py", line 734, in app
    await route.handle(scope, receive, send)
  File "C:\Git_Proj\Order-Management-System\.venv\Lib\site-packages\starlette\routing.py", line 288, in handle
    await self.app(scope, receive, send)
  File "C:\Git_Proj\Order-Management-System\.venv\Lib\site-packages\starlette\routing.py", line 76, in app
    await wrap_app_handling_exceptions(app, request)(scope, receive, send)
  File "C:\Git_Proj\Order-Management-System\.venv\Lib\site-packages\starlette\_exception_handler.py", line 53, in wrapped_app
    raise exc
  File "C:\Git_Proj\Order-Management-System\.venv\Lib\site-packages\starlette\_exception_handler.py", line 42, in wrapped_app
    await app(scope, receive, sender)
  File "C:\Git_Proj\Order-Management-System\.venv\Lib\site-packages\starlette\routing.py", line 73, in app
    response = await f(request)
               ^^^^^^^^^^^^^^^^
  File "C:\Git_Proj\Order-Management-System\.venv\Lib\site-packages\fastapi\routing.py", line 301, in app
    raw_response = await run_endpoint_function(
                   ^^^^^^^^^^^^^^^^^^^^^^^^^^^^
  File "C:\Git_Proj\Order-Management-System\.venv\Lib\site-packages\fastapi\routing.py", line 212, in run_endpoint_function
    return await dependant.call(**values)
           ^^^^^^^^^^^^^^^^^^^^^^^^^^^^^^
  File "C:\Git_Proj\Order-Management-System\app\main.py", line 39, in place_order
    form_data = await request.form()
                ^^^^^^^^^^^^^^^^^^^^
  File "C:\Git_Proj\Order-Management-System\.venv\Lib\site-packages\starlette\requests.py", line 282, in _get_form
    self._form = await form_parser.parse()
                 ^^^^^^^^^^^^^^^^^^^^^^^^^
  File "C:\Git_Proj\Order-Management-System\.venv\Lib\site-packages\starlette\formparsers.py", line 101, in parse
    async for chunk in self.stream:
  File "C:\Git_Proj\Order-Management-System\.venv\Lib\site-packages\starlette\requests.py", line 235, in stream
    raise ClientDisconnect()
starlette.requests.ClientDisconnect
INFO:uvicorn.error:Shutting down
INFO:uvicorn.error:Waiting for application shutdown.
INFO:uvicorn.error:Application shutdown complete.
INFO:uvicorn.error:Finished server process [3552]
INFO:uvicorn.error:Started server process [21724]
INFO:uvicorn.error:Waiting for application startup.
INFO:uvicorn.error:Application startup complete.
INFO:uvicorn.error:Shutting down
INFO:uvicorn.error:Waiting for application shutdown.
INFO:uvicorn.error:Application shutdown complete.
INFO:uvicorn.error:Finished server process [21724]
INFO:uvicorn.error:Started server process [2188]
INFO:uvicorn.error:Waiting for application startup.
INFO:uvicorn.error:Application startup complete.
ERROR:uvicorn.error:Traceback (most recent call last):
  File "C:\Users\D6\AppData\Local\Programs\Python\Python311\Lib\asyncio\runners.py", line 118, in run
    return self._loop.run_until_complete(task)
           ^^^^^^^^^^^^^^^^^^^^^^^^^^^^^^^^^^^
  File "C:\Users\D6\AppData\Local\Programs\Python\Python311\Lib\asyncio\base_events.py", line 654, in run_until_complete
    return future.result()
           ^^^^^^^^^^^^^^^
asyncio.exceptions.CancelledError

During handling of the above exception, another exception occurred:

Traceback (most recent call last):
  File "C:\Users\D6\AppData\Local\Programs\Python\Python311\Lib\asyncio\runners.py", line 190, in run
    return runner.run(main)
           ^^^^^^^^^^^^^^^^
  File "C:\Users\D6\AppData\Local\Programs\Python\Python311\Lib\asyncio\runners.py", line 123, in run
    raise KeyboardInterrupt()
KeyboardInterrupt

During handling of the above exception, another exception occurred:

Traceback (most recent call last):
  File "C:\Git_Proj\Order-Management-System\.venv\Lib\site-packages\starlette\routing.py", line 699, in lifespan
    await receive()
  File "C:\Git_Proj\Order-Management-System\.venv\Lib\site-packages\uvicorn\lifespan\on.py", line 137, in receive
    return await self.receive_queue.get()
           ^^^^^^^^^^^^^^^^^^^^^^^^^^^^^^
  File "C:\Users\D6\AppData\Local\Programs\Python\Python311\Lib\asyncio\queues.py", line 158, in get
    await getter
asyncio.exceptions.CancelledError

INFO:uvicorn.error:Started server process [25656]
INFO:uvicorn.error:Waiting for application startup.
INFO:uvicorn.error:Application startup complete.
INFO:uvicorn.error:Shutting down
INFO:uvicorn.error:Waiting for application shutdown.
INFO:uvicorn.error:Application shutdown complete.
INFO:uvicorn.error:Finished server process [25656]
INFO:uvicorn.error:Started server process [18020]
INFO:uvicorn.error:Waiting for application startup.
INFO:uvicorn.error:Application startup complete.
INFO:root:Form data: FormData([('table_number', '3'), ('1d', '1'), ('1q', '2'), ('2d', '1'), ('2q', '23')])
INFO:uvicorn.error:Shutting down
INFO:uvicorn.error:Waiting for application shutdown.
INFO:uvicorn.error:Application shutdown complete.
INFO:uvicorn.error:Finished server process [18020]
INFO:uvicorn.error:Started server process [19724]
INFO:uvicorn.error:Waiting for application startup.
INFO:uvicorn.error:Application startup complete.
INFO:root:Form data: FormData([('table_number', '3'), ('1d', '1'), ('1q', '2'), ('2d', '1'), ('2q', '23')])
INFO:root:Form data: FormData([('table_number', '3'), ('1d', '1'), ('1q', '2'), ('2d', '1'), ('2q', '23')])
INFO:root:Form data: FormData([('table_number', '3'), ('1d', '1'), ('1q', '2')])
INFO:root:Form data: FormData([('table_number', '3'), ('1d', '1'), ('1q', '2')])
INFO:root:Form data: FormData([('table_number', '3'), ('1d', '1'), ('1q', '2')])
INFO:root:Form data: FormData([('table_number', '3'), ('1d', '1'), ('1q', '2')])
INFO:root:Form data: FormData([('table_number', '3'), ('1d', '1'), ('1q', '2')])
INFO:root:Form data: FormData([('table_number', '3'), ('1d', '1'), ('1q', '2')])
INFO:root:Form data: FormData([('table_number', '3'), ('1d', '1'), ('1q', '2')])
INFO:root:Form data: FormData([('table_number', '3'), ('1d', '1'), ('1q', '2')])
INFO:root:Form data: FormData([('table_number', '3'), ('1d', '1'), ('1q', '2')])
INFO:uvicorn.error:Shutting down
INFO:uvicorn.error:Waiting for application shutdown.
INFO:uvicorn.error:Application shutdown complete.
INFO:uvicorn.error:Finished server process [19724]
INFO:uvicorn.error:Started server process [4176]
INFO:uvicorn.error:Waiting for application startup.
INFO:uvicorn.error:Application startup complete.
ERROR:uvicorn.error:Traceback (most recent call last):
  File "C:\Users\D6\AppData\Local\Programs\Python\Python311\Lib\asyncio\runners.py", line 118, in run
    return self._loop.run_until_complete(task)
           ^^^^^^^^^^^^^^^^^^^^^^^^^^^^^^^^^^^
  File "C:\Users\D6\AppData\Local\Programs\Python\Python311\Lib\asyncio\base_events.py", line 654, in run_until_complete
    return future.result()
           ^^^^^^^^^^^^^^^
asyncio.exceptions.CancelledError

During handling of the above exception, another exception occurred:

Traceback (most recent call last):
  File "C:\Users\D6\AppData\Local\Programs\Python\Python311\Lib\asyncio\runners.py", line 190, in run
    return runner.run(main)
           ^^^^^^^^^^^^^^^^
  File "C:\Users\D6\AppData\Local\Programs\Python\Python311\Lib\asyncio\runners.py", line 123, in run
    raise KeyboardInterrupt()
KeyboardInterrupt

During handling of the above exception, another exception occurred:

Traceback (most recent call last):
  File "C:\Git_Proj\Order-Management-System\.venv\Lib\site-packages\starlette\routing.py", line 699, in lifespan
    await receive()
  File "C:\Git_Proj\Order-Management-System\.venv\Lib\site-packages\uvicorn\lifespan\on.py", line 137, in receive
    return await self.receive_queue.get()
           ^^^^^^^^^^^^^^^^^^^^^^^^^^^^^^
  File "C:\Users\D6\AppData\Local\Programs\Python\Python311\Lib\asyncio\queues.py", line 158, in get
    await getter
asyncio.exceptions.CancelledError

INFO:uvicorn.error:Started server process [21064]
INFO:uvicorn.error:Waiting for application startup.
INFO:uvicorn.error:Application startup complete.
INFO:root:Form data: FormData([('table_number', '2'), ('1d', '1'), ('1q', '21')])
INFO:root:Form data: FormData([('table_number', '2'), ('1d', '1'), ('1q', '43')])
INFO:uvicorn.error:Shutting down
INFO:uvicorn.error:Waiting for application shutdown.
INFO:uvicorn.error:Application shutdown complete.
INFO:uvicorn.error:Finished server process [21064]
INFO:uvicorn.error:Started server process [17452]
INFO:uvicorn.error:Waiting for application startup.
INFO:uvicorn.error:Application startup complete.
